Workbook

Sheet README
A1: Bangladesh Loan Default Risk Dashboard (Excel Template)
A3: What this file does
A4: • Provides a synthetic loan portfolio for multiple Bangladesh banks and a risk model (PD/LGD/ECL).
A5: • Lets you filter by Bank + Month on the Dashboard and see Default Rate, NPL Ratio, and Expected Loss.
A6: • Designed so you can replace the synthetic data with real bank/branch data later.
A8: How to use
A9: 1) Go to 'Dashboard' and pick Bank + Month (cells B2–B3).
A10: 2) (Optional) Adjust PD/LGD stress and weights in 'Assumptions' (blue cells).
A11: 3) Dashboard KPIs + charts update automatically when Excel recalculates.
A13: Where to plug in your own data
A14: • Replace 'Loans' and 'Snapshots' tables with your own extracts.
A15: • Keep the column headers unchanged; Model + KPIs will continue to work.
... A20: • Definitions: PD=Probability of Default, LGD=Loss Given Default, EAD=Exposure at Default, ECL=Expected Credit Loss.

Sheet Lists
A1: Banks | B1: Sectors | C1: Regions | D1: Collateral | E1: Months
A2: AB Bank Limited | B2: Agriculture | C2: Dhaka | D2: Cash | E2: 45658
A3: Agrani Bank Limited | B3: RMG | C3: Chattogram | D3: Real Estate | E3: 45689
A4: Al-Arafah Islami Bank Limited | B4: Trading | C4: Khulna | D4: Vehicle | E4: 45717
A5: Bangladesh Commerce Bank Limited | B5: Construction | C5: Rajshahi | D5: Inventory | E5: 45748
A6: Bangladesh Development Bank Limited | B6: Transport | C6: Sylhet | D6: Unsecured | E6: 45778
A7: Bangladesh Krishi Bank | B7: Services | C7: Barishal | E7: 45809
A8: Bank Asia Limited | B8: Manufacturing | C8: Rangpur | E8: 45839
A9: BASIC Bank Limited | B9: Consumer | C9: Mymensingh | E9: 45870
A10: Bengal Commercial Bank Limited | E10: 45901
A11: BRAC Bank Limited | E11: 45931
A12: Citizens Bank | E12: 45962
A13: City Bank Limited | E13: 45992
A14: Commercial Bank of Ceylon PLC
A15: Community Bank Bangladesh Limited
A16: Dhaka Bank Limited
A17: Dutch-Bangla Bank Limited
A18: Eastern Bank Limited
A19: Export Import Bank of Bangladesh Limited
A20: First Security Islami Bank Limited
A21: Global Islami Bank Limited
A22: ICB Islamic Bank Limited
A23: IFIC Bank Limited
A24: Islami Bank Bangladesh Limited
A25: Jamuna Bank Limited
... A54: Uttara Bank Limited

Sheet Assumptions
A1: Assumptions
A2: Scenario | B2: Base | E2: Scenario Map
A3: PD Stress Multiplier | B3: =VLOOKUP($B$2,$E$4:$G$6,2,FALSE) -> 1 | E3: Scenario | F3: PD Stress | G3: LGD Stress
A4: LGD Stress Multiplier | B4: =VLOOKUP($B$2,$E$4:$G$6,3,FALSE) -> 1 | E4: Base | F4: 1 | G4: 1
A5: PD Logistic Intercept | B5: -3.2 | E5: Mild | F5: 1.15 | G5: 1.1
A6: PD Logistic Beta (RiskScore) | B6: 5 | E6: Severe | F6: 1.35 | G6: 1.25
A8: RiskScore Weights (must be positive) | E8: Sector Risk Factor (0–1)
A9: Weight: DPD | B9: 0.35 | E9: Agriculture | F9: 0.45
A10: Weight: Payment Behavior | B10: 0.2 | E10: RMG | F10: 0.35
A11: Weight: LTV | B11: 0.15 | E11: Trading | F11: 0.4
A12: Weight: Tenure | B12: 0.15 | E12: Construction | F12: 0.55
A13: Weight: Sector | B13: 0.1 | E13: Transport | F13: 0.5
A14: Weight: Restructured | B14: 0.05 | E14: Services | F14: 0.38
E15: Manufacturing | F15: 0.42
A16: PD → Risk Grade Thresholds | E16: Consumer | F16: 0.33
A17: A (Low) | B17: 0.02
A18: B | B18: 0.05
A19: C | B19: 0.1
A20: D | B20: 0.2
A22: LGD by Collateral Type
A23: Cash | B23: 0.2
A24: Real Estate | B24: 0.35
A25: Vehicle | B25: 0.5
A26: Inventory | B26: 0.55
A27: Unsecured | B27: 0.7

Sheet Loans
A1: LoanID | B1: BorrowerID | C1: Bank | D1: Segment | E1: Sector | F1: Region | G1: CollateralType | H1: Product | I1: OriginationDate | J1: MaturityDate | K1: EAD0_BDT | L1: InterestRate | M1: LTV
A2: LN00001 | B2: BORR0047 | C2: BRAC Bank Limited | D2: Retail | E2: Manufacturing | F2: Dhaka | G2: Cash | H2: SME Loan | I2: 43635 | J2: 44001 | K2: 2635691.5 | L2: 0.0926 | M2: 0.773
A3: LN00002 | B3: BORR0440 | C3: Premier Bank Limited | D3: Retail | E3: RMG | F3: Rajshahi | G3: Inventory | H3: SME Loan | I3: 43757 | J3: 44853 | K3: 4886024.5 | L3: 0.0933 | M3: 0.884
A4: LN00003 | B4: BORR0317 | C4: ONE Bank Limited | D4: Retail | E4: RMG | F4: Sylhet | G4: Vehicle | H4: Agri Loan | I4: 43880 | J4: 44976 | K4: 1101780.9 | L4: 0.0968 | M4: 0.783
A5: LN00004 | B5: BORR0295 | C5: Midland Bank Limited | D5: SME | E5: Services | F5: Mymensingh | G5: Vehicle | H5: Auto Loan | I5: 44324 | J5: 45785 | K5: 14280894 | L5: 0.1146 | M5: 0.574
A6: LN00005 | B6: BORR0040 | C6: IFIC Bank Limited | D6: SME | E6: Consumer | F6: Sylhet | G6: Inventory | H6: Term Loan | I6: 43722 | J6: 44453 | K6: 7499060.3 | L6: 0.156 | M6: 0.354
A7: LN00006 | B7: BORR0243 | C7: Uttara Bank Limited | D7: SME | E7: Services | F7: Barishal | G7: Inventory | H7: SME Loan | I7: 44860 | J7: 45956 | K7: 16959388 | L7: 0.1567 | M7: 1.116
A8: LN00007 | B8: BORR0148 | C8: Standard Bank Limited | D8: Retail | E8: Transport | F8: Mymensingh | G8: Real Estate | H8: Auto Loan | I8: 45444 | J8: 47270 | K8: 1906227.7 | L8: 0.1328 | M8: 0.696
A9: LN00008 | B9: BORR0213 | C9: Meghna Bank Limited | D9: Retail | E9: Consumer | F9: Chattogram | G9: Real Estate | H9: Auto Loan | I9: 45051 | J9: 46512 | K9: 4347125.5 | L9: 0.1095 | M9: 0.856
A10: LN00009 | B10: BORR0274 | C10: Janata Bank PLC | D10: SME | E10: Construction | F10: Khulna | G10: Cash | H10: Working Capital | I10: 44143 | J10: 44508 | K10: 16790778 | L10: 0.1109 | M10: 0.825
A11: LN00010 | B11: BORR0247 | C11: Bengal Commercial Bank Limited | D11: SME | E11: Agriculture | F11: Mymensingh | G11: Unsecured | H11: Credit Card/OD | I11: 45987 | J11: 47083 | K11: 8563323 | L11: 0.1236 | M11: 0.971
A12: LN00011 | B12: BORR0448 | C12: Bangladesh Development Bank Limited | D12: Retail | E12: Construction | F12: Mymensingh | G12: Real Estate | H12: Home Loan | I12: 44930 | J12: 45295 | K12: 926071.67 | L12: 0.0971 | M12: 0.817
A13: LN00012 | B13: BORR0160 | C13: SBAC Bank Limited | D13: Retail | E13: Transport | F13: Barishal | G13: Inventory | H13: Auto Loan | I13: 43524 | J13: 44620 | K13: 4893550.4 | L13: 0.1236 | M13: 0.888
... A851: LN00850 | B851: BORR0024 | C851: Social Islami Bank Limited | D851: Agriculture | E851: Manufacturing | F851: Rangpur | G851: Inventory | H851: Credit Card/OD | I851: 45383 | J851: 46844 | K851: 4022676 | L851: 0.0895 | M851: 1.126

Sheet Snapshots
A1: LoanID | B1: Month | C1: OutstandingEAD_BDT | D1: DaysPastDue | E1: InstallmentAmt_BDT | F1: PaidAmt_BDT | G1: PaymentRatio | H1: Restructured | I1: Status
A2: LN00001 | B2: 45658 | C2: 2549146.8 | D2: 0 | E2: 38237.2 | F2: 37503.86 | G2: 0.981 | H2: 0 | I2: Current
A3: LN00001 | B3: 45689 | C3: 2481708 | D3: 0 | E3: 37225.62 | F3: 35502.96 | G3: 0.954 | H3: 0 | I3: Current
A4: LN00001 | B4: 45717 | C4: 2414928.4 | D4: 15 | E4: 36223.93 | F4: 37132.73 | G4: 1.025 | H4: 0 | I4: Current
A5: LN00001 | B5: 45748 | C5: 2350055.8 | D5: 15 | E5: 35250.84 | F5: 37326.22 | G5: 1.059 | H5: 0 | I5: Current
A6: LN00001 | B6: 45778 | C6: 2280207.6 | D6: 0 | E6: 34203.11 | F6: 33912.81 | G6: 0.992 | H6: 0 | I6: Current
A7: LN00001 | B7: 45809 | C7: 2206900.1 | D7: 15 | E7: 33103.5 | F7: 34197.71 | G7: 1.033 | H7: 0 | I7: Current
A8: LN00001 | B8: 45839 | C8: 2144161.2 | D8: 95 | E8: 32162.42 | F8: 19279.15 | G8: 0.599 | H8: 0 | I8: 90+ DPD
A9: LN00001 | B9: 45870 | C9: 2086523.7 | D9: 0 | E9: 31297.86 | F9: 34512.79 | G9: 1.103 | H9: 0 | I9: Current
A10: LN00001 | B10: 45901 | C10: 2030285.4 | D10: 0 | E10: 30454.28 | F10: 32904.45 | G10: 1.08 | H10: 0 | I10: Current
A11: LN00001 | B11: 45931 | C11: 1969886.8 | D11: 0 | E11: 29548.3 | F11: 29765.04 | G11: 1.007 | H11: 0 | I11: Current
A12: LN00001 | B12: 45962 | C12: 1913240.4 | D12: 15 | E12: 28698.61 | F12: 31193.23 | G12: 1.087 | H12: 0 | I12: Current
A13: LN00001 | B13: 45992 | C13: 1858210.2 | D13: 35 | E13: 27873.15 | F13: 20339.79 | G13: 0.73 | H13: 0 | I13: 30-59 DPD
... A9523: LN00850 | B9523: 45992 | C9523: 4022676 | D9523: 999 | E9523: 40226.76 | F9523: 3222.99 | G9523: 0.08 | H9523: 0 | I9523: Default

Sheet Model
A1: LoanID | B1: Bank | C1: Segment | D1: Sector | E1: Region | F1: CollateralType | G1: OriginationDate | H1: Month | I1: OutstandingEAD_BDT | J1: DaysPastDue | K1: PaymentRatio | L1: Restructured | M1: LTV | N1: RiskScore | O1: PD | P1: LGD | Q1: ECL_BDT | R1: RiskGrade | S1: DefaultFlag
A2: LN00001 | B2: BRAC Bank Limited | C2: Retail | D2: Manufacturing | E2: Dhaka | F2: Cash | G2: 43635 | H2: 45689 | I2: 2549146.8 | J2: 0 | K2: 0.981 | L2: 0 | M2: 0.773 | O2: =MIN(1,MAX(0,(1/(1+EXP(-(Assumptions!$B$5 + Assumptions!$B$6*$N2))))*Assumptions!$B$3)) -> 0.039165723 | P2: =VLOOKUP(#REF!,Assumptions!$A$23:$B$27,2,FALSE)*Assumptions!$B$4 -> #REF! | Q2: =$I2*$O2*$P2 -> #REF! | R2: =IF($O2<Assumptions!$B$17,"A",IF($O2<Assumptions!$B$18,"B",IF($O2<Assumptions!$B$19,"C",IF($O2<Assumptions!$B$20,"D","E")))) -> B | S2: =--($J2>=180) -> 0
A3: LN00001 | B3: BRAC Bank Limited | C3: Retail | D3: Manufacturing | E3: Dhaka | F3: Cash | G3: 43635 | H3: 45717 | I3: 2414928.4 | J3: 15 | K3: 1.025 | L3: 0 | M3: 0.773 | O3: =MIN(1,MAX(0,(1/(1+EXP(-(Assumptions!$B$5 + Assumptions!$B$6*$N3))))*Assumptions!$B$3)) -> 0.039165723 | P3: =VLOOKUP($F3,Assumptions!$A$23:$B$27,2,FALSE)*Assumptions!$B$4 -> 0.2 | Q3: =$I3*$O3*$P3 -> 18916.483 | R3: =IF($O3<Assumptions!$B$17,"A",IF($O3<Assumptions!$B$18,"B",IF($O3<Assumptions!$B$19,"C",IF($O3<Assumptions!$B$20,"D","E")))) -> B | S3: =--($J3>=180) -> 0
A4: LN00001 | B4: BRAC Bank Limited | C4: Retail | D4: Manufacturing | E4: Dhaka | F4: Cash | G4: 43635 | H4: 45748 | I4: 2350055.8 | J4: 15 | K4: 1.059 | L4: 0 | M4: 0.773 | O4: =MIN(1,MAX(0,(1/(1+EXP(-(Assumptions!$B$5 + Assumptions!$B$6*$N4))))*Assumptions!$B$3)) -> 0.039165723 | P4: =VLOOKUP($F4,Assumptions!$A$23:$B$27,2,FALSE)*Assumptions!$B$4 -> 0.2 | Q4: =$I4*$O4*$P4 -> 18408.327 | R4: =IF($O4<Assumptions!$B$17,"A",IF($O4<Assumptions!$B$18,"B",IF($O4<Assumptions!$B$19,"C",IF($O4<Assumptions!$B$20,"D","E")))) -> B | S4: =--($J4>=180) -> 0
A5: LN00001 | B5: BRAC Bank Limited | C5: Retail | D5: Manufacturing | E5: Dhaka | F5: Cash | G5: 43635 | H5: 45778 | I5: 2280207.6 | J5: 0 | K5: 0.992 | L5: 0 | M5: 0.773 | O5: =MIN(1,MAX(0,(1/(1+EXP(-(Assumptions!$B$5 + Assumptions!$B$6*$N5))))*Assumptions!$B$3)) -> 0.039165723 | P5: =VLOOKUP($F5,Assumptions!$A$23:$B$27,2,FALSE)*Assumptions!$B$4 -> 0.2 | Q5: =$I5*$O5*$P5 -> 17861.196 | R5: =IF($O5<Assumptions!$B$17,"A",IF($O5<Assumptions!$B$18,"B",IF($O5<Assumptions!$B$19,"C",IF($O5<Assumptions!$B$20,"D","E")))) -> B | S5: =--($J5>=180) -> 0
A6: LN00001 | B6: BRAC Bank Limited | C6: Retail | D6: Manufacturing | E6: Dhaka | F6: Cash | G6: 43635 | H6: 45809 | I6: 2206900.1 | J6: 15 | K6: 1.033 | L6: 0 | M6: 0.773 | O6: =MIN(1,MAX(0,(1/(1+EXP(-(Assumptions!$B$5 + Assumptions!$B$6*$N6))))*Assumptions!$B$3)) -> 0.039165723 | P6: =VLOOKUP($F6,Assumptions!$A$23:$B$27,2,FALSE)*Assumptions!$B$4 -> 0.2 | Q6: =$I6*$O6*$P6 -> 17286.967 | R6: =IF($O6<Assumptions!$B$17,"A",IF($O6<Assumptions!$B$18,"B",IF($O6<Assumptions!$B$19,"C",IF($O6<Assumptions!$B$20,"D","E")))) -> B | S6: =--($J6>=180) -> 0
A7: LN00001 | B7: BRAC Bank Limited | C7: Retail | D7: Manufacturing | E7: Dhaka | F7: Cash | G7: 43635 | H7: 45839 | I7: 2144161.2 | J7: 95 | K7: 0.599 | L7: 0 | M7: 0.773 | O7: =MIN(1,MAX(0,(1/(1+EXP(-(Assumptions!$B$5 + Assumptions!$B$6*$N7))))*Assumptions!$B$3)) -> 0.039165723 | P7: =VLOOKUP($F7,Assumptions!$A$23:$B$27,2,FALSE)*Assumptions!$B$4 -> 0.2 | Q7: =$I7*$O7*$P7 -> 16795.525 | R7: =IF($O7<Assumptions!$B$17,"A",IF($O7<Assumptions!$B$18,"B",IF($O7<Assumptions!$B$19,"C",IF($O7<Assumptions!$B$20,"D","E")))) -> B | S7: =--($J7>=180) -> 0
A8: LN00001 | B8: BRAC Bank Limited | C8: Retail | D8: Manufacturing | E8: Dhaka | F8: Cash | G8: 43635 | H8: 45870 | I8: 2086523.7 | J8: 0 | K8: 1.103 | L8: 0 | M8: 0.773 | O8: =MIN(1,MAX(0,(1/(1+EXP(-(Assumptions!$B$5 + Assumptions!$B$6*$N8))))*Assumptions!$B$3)) -> 0.039165723 | P8: =VLOOKUP($F8,Assumptions!$A$23:$B$27,2,FALSE)*Assumptions!$B$4 -> 0.2 | Q8: =$I8*$O8*$P8 -> 16344.042 | R8: =IF($O8<Assumptions!$B$17,"A",IF($O8<Assumptions!$B$18,"B",IF($O8<Assumptions!$B$19,"C",IF($O8<Assumptions!$B$20,"D","E")))) -> B | S8: =--($J8>=180) -> 0
A9: LN00001 | B9: BRAC Bank Limited | C9: Retail | D9: Manufacturing | E9: Dhaka | F9: Cash | G9: 43635 | H9: 45901 | I9: 2030285.4 | J9: 0 | K9: 1.08 | L9: 0 | M9: 0.773 | O9: =MIN(1,MAX(0,(1/(1+EXP(-(Assumptions!$B$5 + Assumptions!$B$6*$N9))))*Assumptions!$B$3)) -> 0.039165723 | P9: =VLOOKUP($F9,Assumptions!$A$23:$B$27,2,FALSE)*Assumptions!$B$4 -> 0.2 | Q9: =$I9*$O9*$P9 -> 15903.519 | R9: =IF($O9<Assumptions!$B$17,"A",IF($O9<Assumptions!$B$18,"B",IF($O9<Assumptions!$B$19,"C",IF($O9<Assumptions!$B$20,"D","E")))) -> B | S9: =--($J9>=180) -> 0
A10: LN00001 | B10: BRAC Bank Limited | C10: Retail | D10: Manufacturing | E10: Dhaka | F10: Cash | G10: 43635 | H10: 45931 | I10: 1969886.8 | J10: 0 | K10: 1.007 | L10: 0 | M10: 0.773 | O10: =MIN(1,MAX(0,(1/(1+EXP(-(Assumptions!$B$5 + Assumptions!$B$6*$N10))))*Assumptions!$B$3)) -> 0.039165723 | P10: =VLOOKUP($F10,Assumptions!$A$23:$B$27,2,FALSE)*Assumptions!$B$4 -> 0.2 | Q10: =$I10*$O10*$P10 -> 15430.408 | R10: =IF($O10<Assumptions!$B$17,"A",IF($O10<Assumptions!$B$18,"B",IF($O10<Assumptions!$B$19,"C",IF($O10<Assumptions!$B$20,"D","E")))) -> B | S10: =--($J10>=180) -> 0
A11: LN00001 | B11: BRAC Bank Limited | C11: Retail | D11: Manufacturing | E11: Dhaka | F11: Cash | G11: 43635 | H11: 45962 | I11: 1913240.4 | J11: 15 | K11: 1.087 | L11: 0 | M11: 0.773 | O11: =MIN(1,MAX(0,(1/(1+EXP(-(Assumptions!$B$5 + Assumptions!$B$6*$N11))))*Assumptions!$B$3)) -> 0.039165723 | P11: =VLOOKUP($F11,Assumptions!$A$23:$B$27,2,FALSE)*Assumptions!$B$4 -> 0.2 | Q11: =$I11*$O11*$P11 -> 14986.689 | R11: =IF($O11<Assumptions!$B$17,"A",IF($O11<Assumptions!$B$18,"B",IF($O11<Assumptions!$B$19,"C",IF($O11<Assumptions!$B$20,"D","E")))) -> B | S11: =--($J11>=180) -> 0
A12: LN00001 | B12: BRAC Bank Limited | C12: Retail | D12: Manufacturing | E12: Dhaka | F12: Cash | G12: 43635 | H12: 45992 | I12: 1858210.2 | J12: 35 | K12: 0.73 | L12: 0 | M12: 0.773 | O12: =MIN(1,MAX(0,(1/(1+EXP(-(Assumptions!$B$5 + Assumptions!$B$6*$N12))))*Assumptions!$B$3)) -> 0.039165723 | P12: =VLOOKUP($F12,Assumptions!$A$23:$B$27,2,FALSE)*Assumptions!$B$4 -> 0.2 | Q12: =$I12*$O12*$P12 -> 14555.629 | R12: =IF($O12<Assumptions!$B$17,"A",IF($O12<Assumptions!$B$18,"B",IF($O12<Assumptions!$B$19,"C",IF($O12<Assumptions!$B$20,"D","E")))) -> B | S12: =--($J12>=180) -> 0
A13: LN00002 | B13: Premier Bank Limited | C13: Retail | D13: RMG | E13: Rajshahi | F13: Inventory | G13: 43757 | H13: 45658 | I13: 4736390.9 | J13: 0 | K13: 1.126 | L13: 0 | M13: 0.884 | O13: =MIN(1,MAX(0,(1/(1+EXP(-(Assumptions!$B$5 + Assumptions!$B$6*$N13))))*Assumptions!$B$3)) -> 0.039165723 | P13: =VLOOKUP($F13,Assumptions!$A$23:$B$27,2,FALSE)*Assumptions!$B$4 -> 0.55 | Q13: =$I13*$O13*$P13 -> 102027.3 | R13: =IF($O13<Assumptions!$B$17,"A",IF($O13<Assumptions!$B$18,"B",IF($O13<Assumptions!$B$19,"C",IF($O13<Assumptions!$B$20,"D","E")))) -> B | S13: =--($J13>=180) -> 0
A14: LN00002 | B14: Premier Bank Limited | C14: Retail | D14: RMG | E14: Rajshahi | F14: Inventory | G14: 43757 | H14: 45689 | I14: 4602422.8 | J14: 0 | K14: 1.042 | L14: 0 | M14: 0.884 | O14: =MIN(1,MAX(0,(1/(1+EXP(-(Assumptions!$B$5 + Assumptions!$B$6*$N14))))*Assumptions!$B$3)) -> 0.039165723 | P14: =VLOOKUP($F14,Assumptions!$A$23:$B$27,2,FALSE)*Assumptions!$B$4 -> 0.55 | Q14: =$I14*$O14*$P14 -> 99141.469 | R14: =IF($O14<Assumptions!$B$17,"A",IF($O14<Assumptions!$B$18,"B",IF($O14<Assumptions!$B$19,"C",IF($O14<Assumptions!$B$20,"D","E")))) -> B | S14: =--($J14>=180) -> 0
... A9522: LN00850 | B9522: Social Islami Bank Limited | C9522: Agriculture | D9522: Manufacturing | E9522: Rangpur | F9522: Inventory | G9522: 45383 | H9522: 45992 | I9522: 4022676 | J9522: 999 | K9522: 0.08 | L9522: 0 | M9522: 1.126 | O9522: =MIN(1,MAX(0,(1/(1+EXP(-(Assumptions!$B$5 + Assumptions!$B$6*$N9522))))*Assumptions!$B$3)) -> 0.039165723 | P9522: =VLOOKUP($F9522,Assumptions!$A$23:$B$27,2,FALSE)*Assumptions!$B$4 -> 0.55 | Q9522: =$I9522*$O9522*$P9522 -> 86653.058 | R9522: =IF($O9522<Assumptions!$B$17,"A",IF($O9522<Assumptions!$B$18,"B",IF($O9522<Assumptions!$B$19,"C",IF($O9522<Assumptions!$B$20,"D","E")))) -> B | S9522: =--($J9522>=180) -> 1

Sheet Bank_KPIs
A1: Bank-level KPIs (calculated from Model)
B2: Bank | C2: TotalEAD_BDT | D2: DefaultEAD_BDT | E2: NPL90plusEAD_BDT | F2: DefaultRate | G2: NPL_Ratio | H2: ExpectedLoss_BDT
A3: 45658 | B3: AB Bank Limited | C3: =SUMIFS(Model!$I:$I,Model!$H:$H,$A3,Model!$B:$B,$B3) -> 3.1137477e+08 | D3: =SUMIFS(Model!$I:$I,Model!$H:$H,$A3,Model!$B:$B,$B3,Model!$J:$J,">=180") -> 0 | E3: =SUMIFS(Model!$I:$I,Model!$H:$H,$A3,Model!$B:$B,$B3,Model!$J:$J,">=90") -> 0 | F3: =IFERROR($D3/$C3,0) -> 0 | G3: =IFERROR($E3/$C3,0) -> 0 | H3: =SUMIFS(Model!$Q:$Q,Model!$H:$H,$A3,Model!$B:$B,$B3) -> 6577493.4
A4: 45658 | B4: Agrani Bank Limited | C4: =SUMIFS(Model!$I:$I,Model!$H:$H,$A4,Model!$B:$B,$B4) -> 37154299 | D4: =SUMIFS(Model!$I:$I,Model!$H:$H,$A4,Model!$B:$B,$B4,Model!$J:$J,">=180") -> 0 | E4: =SUMIFS(Model!$I:$I,Model!$H:$H,$A4,Model!$B:$B,$B4,Model!$J:$J,">=90") -> 18638903 | F4: =IFERROR($D4/$C4,0) -> 0 | G4: =IFERROR($E4/$C4,0) -> 0.50166207 | H4: =SUMIFS(Model!$Q:$Q,Model!$H:$H,$A4,Model!$B:$B,$B4) -> 798354.41
A5: 45658 | B5: Al-Arafah Islami Bank Limited | C5: =SUMIFS(Model!$I:$I,Model!$H:$H,$A5,Model!$B:$B,$B5) -> 1.2135203e+08 | D5: =SUMIFS(Model!$I:$I,Model!$H:$H,$A5,Model!$B:$B,$B5,Model!$J:$J,">=180") -> 0 | E5: =SUMIFS(Model!$I:$I,Model!$H:$H,$A5,Model!$B:$B,$B5,Model!$J:$J,">=90") -> 0 | F5: =IFERROR($D5/$C5,0) -> 0 | G5: =IFERROR($E5/$C5,0) -> 0 | H5: =SUMIFS(Model!$Q:$Q,Model!$H:$H,$A5,Model!$B:$B,$B5) -> 2245214.3
A6: 45658 | B6: Bangladesh Commerce Bank Limited | C6: =SUMIFS(Model!$I:$I,Model!$H:$H,$A6,Model!$B:$B,$B6) -> 3.0990739e+08 | D6: =SUMIFS(Model!$I:$I,Model!$H:$H,$A6,Model!$B:$B,$B6,Model!$J:$J,">=180") -> 0 | E6: =SUMIFS(Model!$I:$I,Model!$H:$H,$A6,Model!$B:$B,$B6,Model!$J:$J,">=90") -> 0 | F6: =IFERROR($D6/$C6,0) -> 0 | G6: =IFERROR($E6/$C6,0) -> 0 | H6: =SUMIFS(Model!$Q:$Q,Model!$H:$H,$A6,Model!$B:$B,$B6) -> 5111241
A7: 45658 | B7: Bangladesh Development Bank Limited | C7: =SUMIFS(Model!$I:$I,Model!$H:$H,$A7,Model!$B:$B,$B7) -> 1.1235536e+08 | D7: =SUMIFS(Model!$I:$I,Model!$H:$H,$A7,Model!$B:$B,$B7,Model!$J:$J,">=180") -> 22200741 | E7: =SUMIFS(Model!$I:$I,Model!$H:$H,$A7,Model!$B:$B,$B7,Model!$J:$J,">=90") -> 22200741 | F7: =IFERROR($D7/$C7,0) -> 0.19759397 | G7: =IFERROR($E7/$C7,0) -> 0.19759397 | H7: =SUMIFS(Model!$Q:$Q,Model!$H:$H,$A7,Model!$B:$B,$B7) -> 2170418.1
A8: 45658 | B8: Bangladesh Krishi Bank | C8: =SUMIFS(Model!$I:$I,Model!$H:$H,$A8,Model!$B:$B,$B8) -> 2.4060865e+08 | D8: =SUMIFS(Model!$I:$I,Model!$H:$H,$A8,Model!$B:$B,$B8,Model!$J:$J,">=180") -> 0 | E8: =SUMIFS(Model!$I:$I,Model!$H:$H,$A8,Model!$B:$B,$B8,Model!$J:$J,">=90") -> 0 | F8: =IFERROR($D8/$C8,0) -> 0 | G8: =IFERROR($E8/$C8,0) -> 0 | H8: =SUMIFS(Model!$Q:$Q,Model!$H:$H,$A8,Model!$B:$B,$B8) -> 4654826.7
A9: 45658 | B9: Bank Asia Limited | C9: =SUMIFS(Model!$I:$I,Model!$H:$H,$A9,Model!$B:$B,$B9) -> 2.2672547e+08 | D9: =SUMIFS(Model!$I:$I,Model!$H:$H,$A9,Model!$B:$B,$B9,Model!$J:$J,">=180") -> 0 | E9: =SUMIFS(Model!$I:$I,Model!$H:$H,$A9,Model!$B:$B,$B9,Model!$J:$J,">=90") -> 0 | F9: =IFERROR($D9/$C9,0) -> 0 | G9: =IFERROR($E9/$C9,0) -> 0 | H9: =SUMIFS(Model!$Q:$Q,Model!$H:$H,$A9,Model!$B:$B,$B9) -> 3905855.9
A10: 45658 | B10: BASIC Bank Limited | C10: =SUMIFS(Model!$I:$I,Model!$H:$H,$A10,Model!$B:$B,$B10) -> 1.8087128e+08 | D10: =SUMIFS(Model!$I:$I,Model!$H:$H,$A10,Model!$B:$B,$B10,Model!$J:$J,">=180") -> 15896244 | E10: =SUMIFS(Model!$I:$I,Model!$H:$H,$A10,Model!$B:$B,$B10,Model!$J:$J,">=90") -> 15896244 | F10: =IFERROR($D10/$C10,0) -> 0.087887052 | G10: =IFERROR($E10/$C10,0) -> 0.087887052 | H10: =SUMIFS(Model!$Q:$Q,Model!$H:$H,$A10,Model!$B:$B,$B10) -> 3729433.8
A11: 45658 | B11: Bengal Commercial Bank Limited | C11: =SUMIFS(Model!$I:$I,Model!$H:$H,$A11,Model!$B:$B,$B11) -> 4.2525453e+08 | D11: =SUMIFS(Model!$I:$I,Model!$H:$H,$A11,Model!$B:$B,$B11,Model!$J:$J,">=180") -> 0 | E11: =SUMIFS(Model!$I:$I,Model!$H:$H,$A11,Model!$B:$B,$B11,Model!$J:$J,">=90") -> 0 | F11: =IFERROR($D11/$C11,0) -> 0 | G11: =IFERROR($E11/$C11,0) -> 0 | H11: =SUMIFS(Model!$Q:$Q,Model!$H:$H,$A11,Model!$B:$B,$B11) -> 7451861.1
A12: 45658 | B12: BRAC Bank Limited | C12: =SUMIFS(Model!$I:$I,Model!$H:$H,$A12,Model!$B:$B,$B12) -> 5.052045e+08 | D12: =SUMIFS(Model!$I:$I,Model!$H:$H,$A12,Model!$B:$B,$B12,Model!$J:$J,">=180") -> 7100216.9 | E12: =SUMIFS(Model!$I:$I,Model!$H:$H,$A12,Model!$B:$B,$B12,Model!$J:$J,">=90") -> 7100216.9 | F12: =IFERROR($D12/$C12,0) -> 0.014054144 | G12: =IFERROR($E12/$C12,0) -> 0.014054144 | H12: =SUMIFS(Model!$Q:$Q,Model!$H:$H,$A12,Model!$B:$B,$B12) -> 9964798.6
A13: 45658 | B13: Citizens Bank | C13: =SUMIFS(Model!$I:$I,Model!$H:$H,$A13,Model!$B:$B,$B13) -> 3.9232728e+08 | D13: =SUMIFS(Model!$I:$I,Model!$H:$H,$A13,Model!$B:$B,$B13,Model!$J:$J,">=180") -> 0 | E13: =SUMIFS(Model!$I:$I,Model!$H:$H,$A13,Model!$B:$B,$B13,Model!$J:$J,">=90") -> 0 | F13: =IFERROR($D13/$C13,0) -> 0 | G13: =IFERROR($E13/$C13,0) -> 0 | H13: =SUMIFS(Model!$Q:$Q,Model!$H:$H,$A13,Model!$B:$B,$B13) -> 6088959.3
A14: 45658 | B14: City Bank Limited | C14: =SUMIFS(Model!$I:$I,Model!$H:$H,$A14,Model!$B:$B,$B14) -> 1.2825594e+08 | D14: =SUMIFS(Model!$I:$I,Model!$H:$H,$A14,Model!$B:$B,$B14,Model!$J:$J,">=180") -> 0 | E14: =SUMIFS(Model!$I:$I,Model!$H:$H,$A14,Model!$B:$B,$B14,Model!$J:$J,">=90") -> 12469007 | F14: =IFERROR($D14/$C14,0) -> 0 | G14: =IFERROR($E14/$C14,0) -> 0.097219722 | H14: =SUMIFS(Model!$Q:$Q,Model!$H:$H,$A14,Model!$B:$B,$B14) -> 2918974.1
... A638: 45992 | B638: Uttara Bank Limited | C638: =SUMIFS(Model!$I:$I,Model!$H:$H,$A638,Model!$B:$B,$B638) -> 1.3257133e+08 | D638: =SUMIFS(Model!$I:$I,Model!$H:$H,$A638,Model!$B:$B,$B638,Model!$J:$J,">=180") -> 22998385 | E638: =SUMIFS(Model!$I:$I,Model!$H:$H,$A638,Model!$B:$B,$B638,Model!$J:$J,">=90") -> 26439569 | F638: =IFERROR($D638/$C638,0) -> 0.17347933 | G638: =IFERROR($E638/$C638,0) -> 0.19943656 | H638: =SUMIFS(Model!$Q:$Q,Model!$H:$H,$A638,Model!$B:$B,$B638) -> 1970806.6

Sheet Dashboard
A1: Loan Default Risk Dashboard (Bangladesh Banks)
A2: Banks | B2: Dhaka Bank Limited
A3: Month: | B3: 45870
C6: Total EAD (BDT) | D6: Default Rate | E6: NPL Ratio (90+) | F6: Expected Loss (BDT)
C7: =IF($B$2="All",SUMIFS(Bank_KPIs!$C:$C,Bank_KPIs!$A:$A,$B$3),SUMIFS(Bank_KPIs!$C:$C,Bank_KPIs!$A:$A,$B$3,Bank_KPIs!$B:$B,$B$2)) -> 2.3019445e+08 | D7: =IF($B$2="All",IFERROR(SUMIFS(Bank_KPIs!$D:$D,Bank_KPIs!$A:$A,$B$3)/SUMIFS(Bank_KPIs!$C:$C,Bank_KPIs!$A:$A,$B$3),0),IFERROR(SUMIFS(Bank_KPIs!$D:$D,Bank_KPIs!$A:$A,$B$3,Bank_KPIs!$B:$B,$B$2)/SUMIFS(Bank_KPIs!$C:$C,Bank_KPIs!$A:$A,$B$3,Bank_KPIs!$B:$B,$B$2),0)) -> 0.48726595 | E7: =IF($B$2="All",IFERROR(SUMIFS(Bank_KPIs!$E:$E,Bank_KPIs!$A:$A,$B$3)/SUMIFS(Bank_KPIs!$C:$C,Bank_KPIs!$A:$A,$B$3),0),IFERROR(SUMIFS(Bank_KPIs!$E:$E,Bank_KPIs!$A:$A,$B$3,Bank_KPIs!$B:$B,$B$2)/SUMIFS(Bank_KPIs!$C:$C,Bank_KPIs!$A:$A,$B$3,Bank_KPIs!$B:$B,$B$2),0)) -> 0.49010175 | F7: =IF($B$2="All",SUMIFS(Bank_KPIs!$H:$H,Bank_KPIs!$A:$A,$B$3),SUMIFS(Bank_KPIs!$H:$H,Bank_KPIs!$A:$A,$B$3,Bank_KPIs!$B:$B,$B$2)) -> 4608472.9
A9: Monthly trend (for selected Bank)
A10: Month | B10: TotalEAD | C10: DefaultRate | D10: ExpectedLoss
A11: 45658 | B11: =IF($B$2="All",SUMIFS(Bank_KPIs!$C:$C,Bank_KPIs!$A:$A,$A11),SUMIFS(Bank_KPIs!$C:$C,Bank_KPIs!$A:$A,$A11,Bank_KPIs!$B:$B,$B$2)) -> 2.2424496e+08 | C11: =IFERROR(IF($B$2="All",SUMIFS(Bank_KPIs!$D:$D,Bank_KPIs!$A:$A,$A11)/SUMIFS(Bank_KPIs!$C:$C,Bank_KPIs!$A:$A,$A11),SUMIFS(Bank_KPIs!$D:$D,Bank_KPIs!$A:$A,$A11,Bank_KPIs!$B:$B,$B$2)/SUMIFS(Bank_KPIs!$C:$C,Bank_KPIs!$A:$A,$A11,Bank_KPIs!$B:$B,$B$2)),0) -> 0 | D11: =IF($B$2="All",SUMIFS(Bank_KPIs!$H:$H,Bank_KPIs!$A:$A,$A11),SUMIFS(Bank_KPIs!$H:$H,Bank_KPIs!$A:$A,$A11,Bank_KPIs!$B:$B,$B$2)) -> 4254850.1
A12: 45689 | B12: =IF($B$2="All",SUMIFS(Bank_KPIs!$C:$C,Bank_KPIs!$A:$A,$A12),SUMIFS(Bank_KPIs!$C:$C,Bank_KPIs!$A:$A,$A12,Bank_KPIs!$B:$B,$B$2)) -> 2.4192382e+08 | C12: =IFERROR(IF($B$2="All",SUMIFS(Bank_KPIs!$D:$D,Bank_KPIs!$A:$A,$A12)/SUMIFS(Bank_KPIs!$C:$C,Bank_KPIs!$A:$A,$A12),SUMIFS(Bank_KPIs!$D:$D,Bank_KPIs!$A:$A,$A12,Bank_KPIs!$B:$B,$B$2)/SUMIFS(Bank_KPIs!$C:$C,Bank_KPIs!$A:$A,$A12,Bank_KPIs!$B:$B,$B$2)),0) -> 0.013959395 | D12: =IF($B$2="All",SUMIFS(Bank_KPIs!$H:$H,Bank_KPIs!$A:$A,$A12),SUMIFS(Bank_KPIs!$H:$H,Bank_KPIs!$A:$A,$A12,Bank_KPIs!$B:$B,$B$2)) -> 4776607.3
A13: 45717 | B13: =IF($B$2="All",SUMIFS(Bank_KPIs!$C:$C,Bank_KPIs!$A:$A,$A13),SUMIFS(Bank_KPIs!$C:$C,Bank_KPIs!$A:$A,$A13,Bank_KPIs!$B:$B,$B$2)) -> 2.3711667e+08 | C13: =IFERROR(IF($B$2="All",SUMIFS(Bank_KPIs!$D:$D,Bank_KPIs!$A:$A,$A13)/SUMIFS(Bank_KPIs!$C:$C,Bank_KPIs!$A:$A,$A13),SUMIFS(Bank_KPIs!$D:$D,Bank_KPIs!$A:$A,$A13,Bank_KPIs!$B:$B,$B$2)/SUMIFS(Bank_KPIs!$C:$C,Bank_KPIs!$A:$A,$A13,Bank_KPIs!$B:$B,$B$2)),0) -> 0.10626538 | D13: =IF($B$2="All",SUMIFS(Bank_KPIs!$H:$H,Bank_KPIs!$A:$A,$A13),SUMIFS(Bank_KPIs!$H:$H,Bank_KPIs!$A:$A,$A13,Bank_KPIs!$B:$B,$B$2)) -> 4682324.6
A14: 45748 | B14: =IF($B$2="All",SUMIFS(Bank_KPIs!$C:$C,Bank_KPIs!$A:$A,$A14),SUMIFS(Bank_KPIs!$C:$C,Bank_KPIs!$A:$A,$A14,Bank_KPIs!$B:$B,$B$2)) -> 2.3264279e+08 | C14: =IFERROR(IF($B$2="All",SUMIFS(Bank_KPIs!$D:$D,Bank_KPIs!$A:$A,$A14)/SUMIFS(Bank_KPIs!$C:$C,Bank_KPIs!$A:$A,$A14),SUMIFS(Bank_KPIs!$D:$D,Bank_KPIs!$A:$A,$A14,Bank_KPIs!$B:$B,$B$2)/SUMIFS(Bank_KPIs!$C:$C,Bank_KPIs!$A:$A,$A14,Bank_KPIs!$B:$B,$B$2)),0) -> 0.01451629 | D14: =IF($B$2="All",SUMIFS(Bank_KPIs!$H:$H,Bank_KPIs!$A:$A,$A14),SUMIFS(Bank_KPIs!$H:$H,Bank_KPIs!$A:$A,$A14,Bank_KPIs!$B:$B,$B$2)) -> 4594751.3
A15: 45778 | B15: =IF($B$2="All",SUMIFS(Bank_KPIs!$C:$C,Bank_KPIs!$A:$A,$A15),SUMIFS(Bank_KPIs!$C:$C,Bank_KPIs!$A:$A,$A15,Bank_KPIs!$B:$B,$B$2)) -> 2.3211662e+08 | C15: =IFERROR(IF($B$2="All",SUMIFS(Bank_KPIs!$D:$D,Bank_KPIs!$A:$A,$A15)/SUMIFS(Bank_KPIs!$C:$C,Bank_KPIs!$A:$A,$A15),SUMIFS(Bank_KPIs!$D:$D,Bank_KPIs!$A:$A,$A15,Bank_KPIs!$B:$B,$B$2)/SUMIFS(Bank_KPIs!$C:$C,Bank_KPIs!$A:$A,$A15,Bank_KPIs!$B:$B,$B$2)),0) -> 0.014549195 | D15: =IF($B$2="All",SUMIFS(Bank_KPIs!$H:$H,Bank_KPIs!$A:$A,$A15),SUMIFS(Bank_KPIs!$H:$H,Bank_KPIs!$A:$A,$A15,Bank_KPIs!$B:$B,$B$2)) -> 4610807.3
A16: 45809 | B16: =IF($B$2="All",SUMIFS(Bank_KPIs!$C:$C,Bank_KPIs!$A:$A,$A16),SUMIFS(Bank_KPIs!$C:$C,Bank_KPIs!$A:$A,$A16,Bank_KPIs!$B:$B,$B$2)) -> 2.293252e+08 | C16: =IFERROR(IF($B$2="All",SUMIFS(Bank_KPIs!$D:$D,Bank_KPIs!$A:$A,$A16)/SUMIFS(Bank_KPIs!$C:$C,Bank_KPIs!$A:$A,$A16),SUMIFS(Bank_KPIs!$D:$D,Bank_KPIs!$A:$A,$A16,Bank_KPIs!$B:$B,$B$2)/SUMIFS(Bank_KPIs!$C:$C,Bank_KPIs!$A:$A,$A16,Bank_KPIs!$B:$B,$B$2)),0) -> 0.38750691 | D16: =IF($B$2="All",SUMIFS(Bank_KPIs!$H:$H,Bank_KPIs!$A:$A,$A16),SUMIFS(Bank_KPIs!$H:$H,Bank_KPIs!$A:$A,$A16,Bank_KPIs!$B:$B,$B$2)) -> 4557701.2
A17: 45839 | B17: =IF($B$2="All",SUMIFS(Bank_KPIs!$C:$C,Bank_KPIs!$A:$A,$A17),SUMIFS(Bank_KPIs!$C:$C,Bank_KPIs!$A:$A,$A17,Bank_KPIs!$B:$B,$B$2)) -> 2.2863993e+08 | C17: =IFERROR(IF($B$2="All",SUMIFS(Bank_KPIs!$D:$D,Bank_KPIs!$A:$A,$A17)/SUMIFS(Bank_KPIs!$C:$C,Bank_KPIs!$A:$A,$A17),SUMIFS(Bank_KPIs!$D:$D,Bank_KPIs!$A:$A,$A17,Bank_KPIs!$B:$B,$B$2)/SUMIFS(Bank_KPIs!$C:$C,Bank_KPIs!$A:$A,$A17,Bank_KPIs!$B:$B,$B$2)),0) -> 0.37894094 | D17: =IF($B$2="All",SUMIFS(Bank_KPIs!$H:$H,Bank_KPIs!$A:$A,$A17),SUMIFS(Bank_KPIs!$H:$H,Bank_KPIs!$A:$A,$A17,Bank_KPIs!$B:$B,$B$2)) -> 4545387.2
A18: 45870 | B18: =IF($B$2="All",SUMIFS(Bank_KPIs!$C:$C,Bank_KPIs!$A:$A,$A18),SUMIFS(Bank_KPIs!$C:$C,Bank_KPIs!$A:$A,$A18,Bank_KPIs!$B:$B,$B$2)) -> 2.3019445e+08 | C18: =IFERROR(IF($B$2="All",SUMIFS(Bank_KPIs!$D:$D,Bank_KPIs!$A:$A,$A18)/SUMIFS(Bank_KPIs!$C:$C,Bank_KPIs!$A:$A,$A18),SUMIFS(Bank_KPIs!$D:$D,Bank_KPIs!$A:$A,$A18,Bank_KPIs!$B:$B,$B$2)/SUMIFS(Bank_KPIs!$C:$C,Bank_KPIs!$A:$A,$A18,Bank_KPIs!$B:$B,$B$2)),0) -> 0.48726595 | D18: =IF($B$2="All",SUMIFS(Bank_KPIs!$H:$H,Bank_KPIs!$A:$A,$A18),SUMIFS(Bank_KPIs!$H:$H,Bank_KPIs!$A:$A,$A18,Bank_KPIs!$B:$B,$B$2)) -> 4608472.9
A19: 45901 | B19: =IF($B$2="All",SUMIFS(Bank_KPIs!$C:$C,Bank_KPIs!$A:$A,$A19),SUMIFS(Bank_KPIs!$C:$C,Bank_KPIs!$A:$A,$A19,Bank_KPIs!$B:$B,$B$2)) -> 2.2779923e+08 | C19: =IFERROR(IF($B$2="All",SUMIFS(Bank_KPIs!$D:$D,Bank_KPIs!$A:$A,$A19)/SUMIFS(Bank_KPIs!$C:$C,Bank_KPIs!$A:$A,$A19),SUMIFS(Bank_KPIs!$D:$D,Bank_KPIs!$A:$A,$A19,Bank_KPIs!$B:$B,$B$2)/SUMIFS(Bank_KPIs!$C:$C,Bank_KPIs!$A:$A,$A19,Bank_KPIs!$B:$B,$B$2)),0) -> 0.49238937 | D19: =IF($B$2="All",SUMIFS(Bank_KPIs!$H:$H,Bank_KPIs!$A:$A,$A19),SUMIFS(Bank_KPIs!$H:$H,Bank_KPIs!$A:$A,$A19,Bank_KPIs!$B:$B,$B$2)) -> 4561617.1
A20: 45931 | B20: =IF($B$2="All",SUMIFS(Bank_KPIs!$C:$C,Bank_KPIs!$A:$A,$A20),SUMIFS(Bank_KPIs!$C:$C,Bank_KPIs!$A:$A,$A20,Bank_KPIs!$B:$B,$B$2)) -> 2.2558004e+08 | C20: =IFERROR(IF($B$2="All",SUMIFS(Bank_KPIs!$D:$D,Bank_KPIs!$A:$A,$A20)/SUMIFS(Bank_KPIs!$C:$C,Bank_KPIs!$A:$A,$A20),SUMIFS(Bank_KPIs!$D:$D,Bank_KPIs!$A:$A,$A20,Bank_KPIs!$B:$B,$B$2)/SUMIFS(Bank_KPIs!$C:$C,Bank_KPIs!$A:$A,$A20,Bank_KPIs!$B:$B,$B$2)),0) -> 0.49723336 | D20: =IF($B$2="All",SUMIFS(Bank_KPIs!$H:$H,Bank_KPIs!$A:$A,$A20),SUMIFS(Bank_KPIs!$H:$H,Bank_KPIs!$A:$A,$A20,Bank_KPIs!$B:$B,$B$2)) -> 4518905.5
A21: 45962 | B21: =IF($B$2="All",SUMIFS(Bank_KPIs!$C:$C,Bank_KPIs!$A:$A,$A21),SUMIFS(Bank_KPIs!$C:$C,Bank_KPIs!$A:$A,$A21,Bank_KPIs!$B:$B,$B$2)) -> 2.2335518e+08 | C21: =IFERROR(IF($B$2="All",SUMIFS(Bank_KPIs!$D:$D,Bank_KPIs!$A:$A,$A21)/SUMIFS(Bank_KPIs!$C:$C,Bank_KPIs!$A:$A,$A21),SUMIFS(Bank_KPIs!$D:$D,Bank_KPIs!$A:$A,$A21,Bank_KPIs!$B:$B,$B$2)/SUMIFS(Bank_KPIs!$C:$C,Bank_KPIs!$A:$A,$A21,Bank_KPIs!$B:$B,$B$2)),0) -> 0.50218633 | D21: =IF($B$2="All",SUMIFS(Bank_KPIs!$H:$H,Bank_KPIs!$A:$A,$A21),SUMIFS(Bank_KPIs!$H:$H,Bank_KPIs!$A:$A,$A21,Bank_KPIs!$B:$B,$B$2)) -> 4476185.6
A22: 45992 | B22: =IF($B$2="All",SUMIFS(Bank_KPIs!$C:$C,Bank_KPIs!$A:$A,$A22),SUMIFS(Bank_KPIs!$C:$C,Bank_KPIs!$A:$A,$A22,Bank_KPIs!$B:$B,$B$2)) -> 2.2112033e+08 | C22: =IFERROR(IF($B$2="All",SUMIFS(Bank_KPIs!$D:$D,Bank_KPIs!$A:$A,$A22)/SUMIFS(Bank_KPIs!$C:$C,Bank_KPIs!$A:$A,$A22),SUMIFS(Bank_KPIs!$D:$D,Bank_KPIs!$A:$A,$A22,Bank_KPIs!$B:$B,$B$2)/SUMIFS(Bank_KPIs!$C:$C,Bank_KPIs!$A:$A,$A22,Bank_KPIs!$B:$B,$B$2)),0) -> 0.5072619 | D22: =IF($B$2="All",SUMIFS(Bank_KPIs!$H:$H,Bank_KPIs!$A:$A,$A22),SUMIFS(Bank_KPIs!$H:$H,Bank_KPIs!$A:$A,$A22,Bank_KPIs!$B:$B,$B$2)) -> 4433956.9
A25: Exposure by Sector (selected Bank + Month)
A26: Sector | B26: EAD
A27: Agriculture | B27: =IF($B$2="All",SUMIFS(Model!$I:$I,Model!$H:$H,$B$3,Model!$D:$D,$A27),SUMIFS(Model!$I:$I,Model!$H:$H,$B$3,Model!$B:$B,$B$2,Model!$D:$D,$A27)) -> 8372750.4
A28: RMG | B28: =IF($B$2="All",SUMIFS(Model!$I:$I,Model!$H:$H,$B$3,Model!$D:$D,$A28),SUMIFS(Model!$I:$I,Model!$H:$H,$B$3,Model!$B:$B,$B$2,Model!$D:$D,$A28)) -> 13005111
A29: Trading | B29: =IF($B$2="All",SUMIFS(Model!$I:$I,Model!$H:$H,$B$3,Model!$D:$D,$A29),SUMIFS(Model!$I:$I,Model!$H:$H,$B$3,Model!$B:$B,$B$2,Model!$D:$D,$A29)) -> 0
A30: Construction | B30: =IF($B$2="All",SUMIFS(Model!$I:$I,Model!$H:$H,$B$3,Model!$D:$D,$A30),SUMIFS(Model!$I:$I,Model!$H:$H,$B$3,Model!$B:$B,$B$2,Model!$D:$D,$A30)) -> 24795700
A31: Transport | B31: =IF($B$2="All",SUMIFS(Model!$I:$I,Model!$H:$H,$B$3,Model!$D:$D,$A31),SUMIFS(Model!$I:$I,Model!$H:$H,$B$3,Model!$B:$B,$B$2,Model!$D:$D,$A31)) -> 32548373
A32: Services | B32: =IF($B$2="All",SUMIFS(Model!$I:$I,Model!$H:$H,$B$3,Model!$D:$D,$A32),SUMIFS(Model!$I:$I,Model!$H:$H,$B$3,Model!$B:$B,$B$2,Model!$D:$D,$A32)) -> 95420430
A33: Manufacturing | B33: =IF($B$2="All",SUMIFS(Model!$I:$I,Model!$H:$H,$B$3,Model!$D:$D,$A33),SUMIFS(Model!$I:$I,Model!$H:$H,$B$3,Model!$B:$B,$B$2,Model!$D:$D,$A33)) -> 7857374.7
A34: Consumer | B34: =IF($B$2="All",SUMIFS(Model!$I:$I,Model!$H:$H,$B$3,Model!$D:$D,$A34),SUMIFS(Model!$I:$I,Model!$H:$H,$B$3,Model!$B:$B,$B$2,Model!$D:$D,$A34)) -> 48194717
A37: NPL Ratio by Bank (selected Month)
A38: Bank | B38: NPL Ratio
A39: AB Bank Limited | B39: =IFERROR(SUMIFS(Bank_KPIs!$E:$E,Bank_KPIs!$A:$A,$B$3,Bank_KPIs!$B:$B,$A39)/SUMIFS(Bank_KPIs!$C:$C,Bank_KPIs!$A:$A,$B$3,Bank_KPIs!$B:$B,$A39),0) -> 0.39869251
A40: Agrani Bank Limited | B40: =IFERROR(SUMIFS(Bank_KPIs!$E:$E,Bank_KPIs!$A:$A,$B$3,Bank_KPIs!$B:$B,$A40)/SUMIFS(Bank_KPIs!$C:$C,Bank_KPIs!$A:$A,$B$3,Bank_KPIs!$B:$B,$A40),0) -> 0
A41: Al-Arafah Islami Bank Limited | B41: =IFERROR(SUMIFS(Bank_KPIs!$E:$E,Bank_KPIs!$A:$A,$B$3,Bank_KPIs!$B:$B,$A41)/SUMIFS(Bank_KPIs!$C:$C,Bank_KPIs!$A:$A,$B$3,Bank_KPIs!$B:$B,$A41),0) -> 0.10364655
A42: Bangladesh Commerce Bank Limited | B42: =IFERROR(SUMIFS(Bank_KPIs!$E:$E,Bank_KPIs!$A:$A,$B$3,Bank_KPIs!$B:$B,$A42)/SUMIFS(Bank_KPIs!$C:$C,Bank_KPIs!$A:$A,$B$3,Bank_KPIs!$B:$B,$A42),0) -> 0.047088804
A43: Bangladesh Development Bank Limited | B43: =IFERROR(SUMIFS(Bank_KPIs!$E:$E,Bank_KPIs!$A:$A,$B$3,Bank_KPIs!$B:$B,$A43)/SUMIFS(Bank_KPIs!$C:$C,Bank_KPIs!$A:$A,$B$3,Bank_KPIs!$B:$B,$A43),0) -> 0.1064437
A44: Bangladesh Krishi Bank | B44: =IFERROR(SUMIFS(Bank_KPIs!$E:$E,Bank_KPIs!$A:$A,$B$3,Bank_KPIs!$B:$B,$A44)/SUMIFS(Bank_KPIs!$C:$C,Bank_KPIs!$A:$A,$B$3,Bank_KPIs!$B:$B,$A44),0) -> 0.42248203
A45: Bank Asia Limited | B45: =IFERROR(SUMIFS(Bank_KPIs!$E:$E,Bank_KPIs!$A:$A,$B$3,Bank_KPIs!$B:$B,$A45)/SUMIFS(Bank_KPIs!$C:$C,Bank_KPIs!$A:$A,$B$3,Bank_KPIs!$B:$B,$A45),0) -> 0.25714501
A46: BASIC Bank Limited | B46: =IFERROR(SUMIFS(Bank_KPIs!$E:$E,Bank_KPIs!$A:$A,$B$3,Bank_KPIs!$B:$B,$A46)/SUMIFS(Bank_KPIs!$C:$C,Bank_KPIs!$A:$A,$B$3,Bank_KPIs!$B:$B,$A46),0) -> 0.16329436
A47: Bengal Commercial Bank Limited | B47: =IFERROR(SUMIFS(Bank_KPIs!$E:$E,Bank_KPIs!$A:$A,$B$3,Bank_KPIs!$B:$B,$A47)/SUMIFS(Bank_KPIs!$C:$C,Bank_KPIs!$A:$A,$B$3,Bank_KPIs!$B:$B,$A47),0) -> 0.30020308
...
